<?xml version="1.0" ?>
<!-- =================================================================================== -->
<!-- |    This document was autogenerated by xacro from rab.urdf.xacro                 | -->
<!-- |    EDITING THIS FILE BY HAND IS NOT RECOMMENDED                                 | -->
<!-- =================================================================================== -->
<robot name="rab" xmlns:xacro="http://ros.org/wiki/xacro">
  <!-- ============== Link & Joint =================== -->
  <!-- base -->
  <link name="base_footprint"/>
  <joint name="base_link_joint" type="fixed">
    <origin xyz="0 0 0"/>
    <parent link="base_footprint"/>
    <child link="base_link"/>
  </joint>
  <link name="base_link">
    <visual>
      <geometry>
        <mesh filename="package://rab_description/meshes/DAE/base/base_link.dae"/>
      </geometry>
    </visual>
    <collision>
      <geometry>
        <mesh filename="package://rab_description/meshes/STL/base_link.stl"/>
      </geometry>
    </collision>
    <inertial>
      <origin xyz="0 0 0.11"/>
      <mass value="20.0"/>
      <inertia ixx="2.2230" ixy="0" ixz="0" iyy="3.3236" iyz="0" izz="2.5307"/>
    </inertial>
  </link>
  <!-- wheel -->
  <!-- right_wheel -->
  <joint name="right_wheel_joint" type="continuous">
    <origin xyz="0 -0.24 0"/>
    <parent link="base_link"/>
    <child link="right_wheel_link"/>
    <axis xyz="0 1 0"/>
  </joint>
  <link name="right_wheel_link">
    <visual>
      <geometry>
        <mesh filename="package://rab_description/meshes/DAE/wheel/right_wheel_link.dae"/>
      </geometry>
    </visual>
    <collision>
      <origin rpy="-1.57079637 0 0" xyz="0 -0.003 0"/>
      <geometry>
        <cylinder length="0.045" radius="0.11"/>
      </geometry>
    </collision>
    <inertial>
      <origin rpy="1.57079637 0 0" xyz="0 -0.003 0"/>
      <mass value="1.0"/>
      <inertia ixx="0.00319375" ixy="0" ixz="0" iyy="0.00319375" iyz="0" izz="0.00605"/>
    </inertial>
  </link>
  <!-- left_wheel -->
  <joint name="left_wheel_joint" type="continuous">
    <origin xyz="0 0.24 0"/>
    <parent link="base_link"/>
    <child link="left_wheel_link"/>
    <axis xyz="0 -1 0"/>
  </joint>
  <link name="left_wheel_link">
    <visual>
      <geometry>
        <mesh filename="package://rab_description/meshes/DAE/wheel/left_wheel_link.dae"/>
      </geometry>
    </visual>
    <collision>
      <origin rpy="-1.57079637 0 0" xyz="0 -0.003 0"/>
      <geometry>
        <cylinder length="0.045" radius="0.11"/>
      </geometry>
    </collision>
    <inertial>
      <origin rpy="1.57079637 0 0" xyz="0 -0.003 0"/>
      <mass value="1.0"/>
      <inertia ixx="0.00319375" ixy="0" ixz="0" iyy="0.00319375" iyz="0" izz="0.00605"/>
    </inertial>
  </link>
  <!-- sensors -->
  <!-- right_lrf -->
  <joint name="right_lrf_joint" type="fixed">
    <origin rpy="0 0 1.57" xyz="0 0.2305 0.137"/>
    <parent link="base_link"/>
    <child link="right_lrf_link"/>
  </joint>
  <link name="right_lrf_link">
    <visual>
      <geometry>
        <mesh filename="package://rab_description/meshes/DAE/lrf/right_lrf_link.dae"/>
      </geometry>
    </visual>
    <collision>
      <geometry>
        <mesh filename="package://rab_description/meshes/STL/{prefix}_lrf_link.stl"/>
      </geometry>
    </collision>
    <inertial>
      <origin xyz="0 0 -0.0164"/>
      <mass value="0.4"/>
      <inertia ixx="0.00254666666667" ixy="0" ixz="0" iyy="0.000376666666667" iyz="0" izz="0.000326666666667"/>
    </inertial>
  </link>
  <!-- left_lrf -->
  <joint name="left_lrf_joint" type="fixed">
    <origin rpy="0 0 -1.57" xyz="0 -0.2305 0.137"/>
    <parent link="base_link"/>
    <child link="left_lrf_link"/>
  </joint>
  <link name="left_lrf_link">
    <visual>
      <geometry>
        <mesh filename="package://rab_description/meshes/DAE/lrf/left_lrf_link.dae"/>
      </geometry>
    </visual>
    <collision>
      <geometry>
        <mesh filename="package://rab_description/meshes/STL/{prefix}_lrf_link.stl"/>
      </geometry>
    </collision>
    <inertial>
      <origin xyz="0 0 -0.0164"/>
      <mass value="0.4"/>
      <inertia ixx="0.00254666666667" ixy="0" ixz="0" iyy="0.000376666666667" iyz="0" izz="0.000326666666667"/>
    </inertial>
  </link>
  <link name="lrf_link"/>
  <joint name="lrf_link_joint" type="fixed">
    <parent link="base_link"/>
    <child link="lrf_link"/>
    <origin xyz="0 0 0.137"/>
  </joint>
  <!-- =========== transmission ============= -->
  <transmission name="right_wheel_trans">
    <type>transmission_interface/SimpleTransmission</type>
    <joint name="right_wheel_joint">
      <hardwareInterface>VelocityJointInterface</hardwareInterface>
    </joint>
    <actuator name="right_wheel_motor">
      <hardwareInterface>VelocityJointInterface</hardwareInterface>
      <mechanicalReduction>30</mechanicalReduction>
    </actuator>
  </transmission>
  <transmission name="left_wheel_trans">
    <type>transmission_interface/SimpleTransmission</type>
    <joint name="left_wheel_joint">
      <hardwareInterface>VelocityJointInterface</hardwareInterface>
    </joint>
    <actuator name="left_wheel_motor">
      <hardwareInterface>VelocityJointInterface</hardwareInterface>
      <mechanicalReduction>30</mechanicalReduction>
    </actuator>
  </transmission>
  <!-- =========== gazebo ============ -->
  <gazebo>
    <plugin filename="libgazebo_ros_control.so" name="gazebo_ros_control"/>
  </gazebo>
  <!-- base -->
  <gazebo reference="base_link">
    <selfCollide>false</selfCollide>
    <mu1 value="0.05"/>
    <mu2 value="0.05"/>
  </gazebo>
  <!-- wheel -->
  <gazebo reference="right_wheel_link">
    <selfCollide>false</selfCollide>
    <mu1 value="0.8"/>
    <mu2 value="0.8"/>
  </gazebo>
  <gazebo reference="left_wheel_link">
    <selfCollide>false</selfCollide>
    <mu1 value="0.8"/>
    <mu2 value="0.8"/>
  </gazebo>
  <!-- LRF -->
  <gazebo reference="right_lrf_link">
    <sensor name="right_lrf_sensor" type="ray">
      <pose>0 0 0 0 0 0</pose>
      <visualize>true</visualize>
      <update_rate>40</update_rate>
      <ray>
        <scan>
          <horizontal>
            <samples>720</samples>
            <resolution>1</resolution>
            <min_angle>-2.35619449019</min_angle>
            <max_angle>1.69297</max_angle>
          </horizontal>
        </scan>
        <range>
          <min>0.1</min>
          <max>30.0</max>
          <resolution>0.01</resolution>
        </range>
        <noise>
          <type>gaussian</type>
          <mean>0.0</mean>
          <stddev>0.03</stddev>
        </noise>
      </ray>
      <plugin filename="libgazebo_ros_laser.so" name="gazebo_ros_right_lrf_controller">
        <topicName>right/first</topicName>
        <frameName>right_lrf_link</frameName>
      </plugin>
    </sensor>
  </gazebo>
  <gazebo reference="left_lrf_link">
    <sensor name="left_lrf_sensor" type="ray">
      <pose>0 0 0 0 0 0</pose>
      <visualize>true</visualize>
      <update_rate>40</update_rate>
      <ray>
        <scan>
          <horizontal>
            <samples>720</samples>
            <resolution>1</resolution>
            <min_angle>-1.69297</min_angle>
            <max_angle>2.35619449019</max_angle>
          </horizontal>
        </scan>
        <range>
          <min>0.1</min>
          <max>30.0</max>
          <resolution>0.01</resolution>
        </range>
        <noise>
          <type>gaussian</type>
          <mean>0.0</mean>
          <stddev>0.03</stddev>
        </noise>
      </ray>
      <plugin filename="libgazebo_ros_laser.so" name="gazebo_ros_left_lrf_controller">
        <topicName>left/first</topicName>
        <frameName>left_lrf_link</frameName>
      </plugin>
    </sensor>
  </gazebo>
</robot>

